<?xml version="1.0" ?>
<!-- =================================================================================== -->
<!-- |    This document was autogenerated by xacro from /home/fjulian/Code/ros_manipulation_ws/src/high_level_planning_private/highlevel_planning/data/models/cupboard2/cupboard2.urdf.xacro | -->
<!-- |    EDITING THIS FILE BY HAND IS NOT RECOMMENDED                                 | -->
<!-- =================================================================================== -->
<robot name="cupboard_drawers">
  <material name="white">
    <color rgba="1 1 1 1"/>
  </material>
  <material name="dark_brown">
    <color rgba="0.4 0.2 0.0 1"/>
  </material>
  <material name="light_brown">
    <color rgba="0.6 0.29 0.0 1"/>
  </material>
  <material name="silver">
    <color rgba="0.87 0.87 0.87 0.8"/>
  </material>
  <link name="base_link">
    <inertial>
      <origin rpy="0 0 0" xyz="0 0 0"/>
      <mass value="0.0"/>
      <inertia ixx="1" ixy="0" ixz="0" iyy="1" iyz="0" izz="1"/>
    </inertial>
  </link>
  <link name="corpus_link">
    <contact>
      <lateral_friction value="1.0"/>
    </contact>
    <inertial>
      <origin rpy="0 0 0" xyz="0 0 0"/>
      <mass value="30"/>
      <inertia ixx="1" ixy="0" ixz="0" iyy="1" iyz="0" izz="1"/>
    </inertial>
    <collision>
      <origin rpy="0 0 0" xyz="0 0 0"/>
      <geometry>
        <mesh filename="corpus.stl"/>
      </geometry>
    </collision>
    <visual>
      <origin rpy="0 0 0" xyz="0 0 0"/>
      <geometry>
        <mesh filename="corpus.stl"/>
      </geometry>
      <material name="dark_brown"/>
    </visual>
  </link>
  <joint name="frame_joint" type="fixed">
    <origin rpy="0 0 0" xyz="0 0 0"/>
    <parent link="base_link"/>
    <child link="corpus_link"/>
  </joint>
  <link name="drawer1_link">
    <contact>
      <lateral_friction value="1.0"/>
    </contact>
    <inertial>
      <origin rpy="0 0 0" xyz="0 0 0"/>
      <mass value="30"/>
      <inertia ixx="1" ixy="0" ixz="0" iyy="1" iyz="0" izz="1"/>
    </inertial>
    <collision>
      <origin rpy="0 0 0" xyz="0 0 0"/>
      <geometry>
        <mesh filename="drawer.stl"/>
      </geometry>
    </collision>
    <visual>
      <origin rpy="0 0 0" xyz="0 0 0"/>
      <geometry>
        <mesh filename="drawer.stl"/>
      </geometry>
      <material name="light_brown"/>
    </visual>
  </link>
  <joint name="drawer_joint1" type="prismatic">
    <origin rpy="0 0 0" xyz="0 0 0.005"/>
    <parent link="base_link"/>
    <child link="drawer1_link"/>
    <axis xyz="0 -1 0"/>
    <dynamics damping="8.0"/>
    <limit effort="10.0" lower="0.0" upper="0.65" velocity="1.5"/>
  </joint>
  <link name="drawer2_link">
    <contact>
      <lateral_friction value="1.0"/>
    </contact>
    <inertial>
      <origin rpy="0 0 0" xyz="0 0 0"/>
      <mass value="30"/>
      <inertia ixx="1" ixy="0" ixz="0" iyy="1" iyz="0" izz="1"/>
    </inertial>
    <collision>
      <origin rpy="0 0 0" xyz="0 0 0"/>
      <geometry>
        <mesh filename="drawer.stl"/>
      </geometry>
    </collision>
    <visual>
      <origin rpy="0 0 0" xyz="0 0 0"/>
      <geometry>
        <mesh filename="drawer.stl"/>
      </geometry>
      <material name="light_brown"/>
    </visual>
  </link>
  <joint name="drawer_joint2" type="prismatic">
    <origin rpy="0 0 0" xyz="0 0 0.248"/>
    <parent link="base_link"/>
    <child link="drawer2_link"/>
    <axis xyz="0 -1 0"/>
    <dynamics damping="8.0"/>
    <limit effort="10.0" lower="0.0" upper="0.65" velocity="1.5"/>
  </joint>
  <link name="drawer3_link">
    <contact>
      <lateral_friction value="1.0"/>
    </contact>
    <inertial>
      <origin rpy="0 0 0" xyz="0 0 0"/>
      <mass value="30"/>
      <inertia ixx="1" ixy="0" ixz="0" iyy="1" iyz="0" izz="1"/>
    </inertial>
    <collision>
      <origin rpy="0 0 0" xyz="0 0 0"/>
      <geometry>
        <mesh filename="drawer.stl"/>
      </geometry>
    </collision>
    <visual>
      <origin rpy="0 0 0" xyz="0 0 0"/>
      <geometry>
        <mesh filename="drawer.stl"/>
      </geometry>
      <material name="light_brown"/>
    </visual>
  </link>
  <joint name="drawer_joint3" type="prismatic">
    <origin rpy="0 0 0" xyz="0 0 0.491"/>
    <parent link="base_link"/>
    <child link="drawer3_link"/>
    <axis xyz="0 -1 0"/>
    <dynamics damping="8.0"/>
    <limit effort="10.0" lower="0.0" upper="0.65" velocity="1.5"/>
  </joint>
  <link name="drawer4_link">
    <contact>
      <lateral_friction value="1.0"/>
    </contact>
    <inertial>
      <origin rpy="0 0 0" xyz="0 0 0"/>
      <mass value="30"/>
      <inertia ixx="1" ixy="0" ixz="0" iyy="1" iyz="0" izz="1"/>
    </inertial>
    <collision>
      <origin rpy="0 0 0" xyz="0 0 0"/>
      <geometry>
        <mesh filename="drawer.stl"/>
      </geometry>
    </collision>
    <visual>
      <origin rpy="0 0 0" xyz="0 0 0"/>
      <geometry>
        <mesh filename="drawer.stl"/>
      </geometry>
      <material name="light_brown"/>
    </visual>
  </link>
  <joint name="drawer_joint4" type="prismatic">
    <origin rpy="0 0 0" xyz="0 0 0.734"/>
    <parent link="base_link"/>
    <child link="drawer4_link"/>
    <axis xyz="0 -1 0"/>
    <dynamics damping="8.0"/>
    <limit effort="10.0" lower="0.0" upper="0.65" velocity="1.5"/>
  </joint>
</robot>

